nohup: ignoring input
2025-05-10 00:15:33.972580: I tensorflow/core/util/port.cc:153] oneDNN custom operations are on. You may see slightly different numerical results due to floating-point round-off errors from different computation orders. To turn them off, set the environment variable `TF_ENABLE_ONEDNN_OPTS=0`.
2025-05-10 00:15:33.982948: E external/local_xla/xla/stream_executor/cuda/cuda_fft.cc:467] Unable to register cuFFT factory: Attempting to register factory for plugin cuFFT when one has already been registered
WARNING: All log messages before absl::InitializeLog() is called are written to STDERR
E0000 00:00:1746832533.995230 3488699 cuda_dnn.cc:8579] Unable to register cuDNN factory: Attempting to register factory for plugin cuDNN when one has already been registered
E0000 00:00:1746832533.998897 3488699 cuda_blas.cc:1407] Unable to register cuBLAS factory: Attempting to register factory for plugin cuBLAS when one has already been registered
W0000 00:00:1746832534.008612 3488699 computation_placer.cc:177] computation placer already registered. Please check linkage and avoid linking the same target more than once.
W0000 00:00:1746832534.008636 3488699 computation_placer.cc:177] computation placer already registered. Please check linkage and avoid linking the same target more than once.
W0000 00:00:1746832534.008638 3488699 computation_placer.cc:177] computation placer already registered. Please check linkage and avoid linking the same target more than once.
W0000 00:00:1746832534.008639 3488699 computation_placer.cc:177] computation placer already registered. Please check linkage and avoid linking the same target more than once.
2025-05-10 00:15:34.011450: I tensorflow/core/platform/cpu_feature_guard.cc:210] This TensorFlow binary is optimized to use available CPU instructions in performance-critical operations.
To enable the following instructions: AVX2 AVX512F AVX512_VNNI AVX512_BF16 AVX512_FP16 AVX_VNNI AMX_TILE AMX_INT8 AMX_BF16 FMA, in other operations, rebuild TensorFlow with the appropriate compiler flags.
2025-05-10 00:15:36,091   INFO : ======================================================================

2025-05-10 00:15:36,091   INFO : üöÄ Starting MATG: Multi-Agent LLM-Based Test Generation Framework
2025-05-10 00:15:36,091   INFO : üìò Purpose : Automated test generation for Java using LLM agents
2025-05-10 00:15:36,091   INFO : üß† Agents  : Planner, Generator, Executor, and Evaluator
2025-05-10 00:15:36,091   INFO : üõ†Ô∏è  Engine  : Powered by matg (Machine-Assisted Test Generation)
2025-05-10 00:15:36,091   INFO : ======================================================================


2025-05-10 00:15:36,234   ERROR : Error generating test cases: File '/home/qinghua/projects/matg/data/HumanEvalJava/matg/target/site/jacoco/jacoco.xml' not found.
Traceback (most recent call last):
  File "<frozen runpy>", line 198, in _run_module_as_main
  File "<frozen runpy>", line 88, in _run_code
  File "/home/qinghua/projects/matg/main.py", line 71, in <module>
    main()
  File "/home/qinghua/projects/matg/main.py", line 68, in main
    test_generator.run()
  File "/home/qinghua/projects/matg/generate.py", line 120, in run
    logger.info(f"Final line coverage: {self.line_coverage}")
                                        ^^^^^^^^^^^^^^^^^^
AttributeError: 'TestCaseGenerator' object has no attribute 'line_coverage'



                                    ‚ñà‚ñà‚ñà    ‚ñà‚ñà‚ñà      ‚ñà‚ñà‚ñà‚ñà‚ñà     ‚ñà‚ñà‚ñà‚ñà‚ñà‚ñà‚ñà       ‚ñà‚ñà‚ñà‚ñà‚ñà‚ñà  
                                    ‚ñà‚ñà‚ñà‚ñà  ‚ñà‚ñà‚ñà‚ñà     ‚ñà‚ñà   ‚ñà‚ñà      ‚ñà‚ñà‚ñà      ‚ñà‚ñà    
                                    ‚ñà‚ñà ‚ñà‚ñà‚ñà‚ñà ‚ñà‚ñà     ‚ñà‚ñà‚ñà‚ñà‚ñà‚ñà‚ñà      ‚ñà‚ñà‚ñà      ‚ñà‚ñà   ‚ñà‚ñà‚ñà‚ñà
                                    ‚ñà‚ñà  ‚ñà‚ñà  ‚ñà‚ñà     ‚ñà‚ñà   ‚ñà‚ñà      ‚ñà‚ñà‚ñà      ‚ñà‚ñà     ‚ñà‚ñà 
                                    ‚ñà‚ñà      ‚ñà‚ñà     ‚ñà‚ñà   ‚ñà‚ñà      ‚ñà‚ñà‚ñà        ‚ñà‚ñà‚ñà‚ñà‚ñà‚ñà‚ñà  

Traceback (most recent call last):
  File "<frozen runpy>", line 198, in _run_module_as_main
  File "<frozen runpy>", line 88, in _run_code
  File "/home/qinghua/projects/matg/experiments/preliminary/generate/run.py", line 30, in <module>
    subprocess.run(command, check=True)
  File "/home/qinghua/anaconda3/envs/llm4test/lib/python3.11/subprocess.py", line 571, in run
    raise CalledProcessError(retcode, process.args,
subprocess.CalledProcessError: Command '['python', '-m', 'matg.main', 'generate', '--data-path', '/home/qinghua/projects/matg/data/HumanEvalJava/matg', '--relative-source-file-path', 'src/main/java/original/id_142.java', '--relative-test-file-path', 'src/test/java/original/id_142Test.java', '--coverage-report-path', '/home/qinghua/projects/matg/data/HumanEvalJava/matg/target/site/jacoco', '--test-command', 'mvn -f /home/qinghua/projects/matg/data/HumanEvalJava/matg/pom.xml clean test jacoco:report', '--generator', 'matg', '--max-attempts', '3', '--target-line-coverage', '0.99']' returned non-zero exit status 1.
